<?xml version='1.0' encoding='utf-8'?>
<robot name="robotic_arm_6dof">
    <material name="green">
        <color rgba="0 0.6 0 1" />
    </material>
    <material name="orange">
        <color rgba="1.0 0.4 0.0 1.0"/>
    </material>

    <link name="base_link">
        <inertial>
            <origin xyz="0.0007383995830932366 0.016066406007732476 0.1863534219304777" rpy="0.0 0.0 0.0" />
            <mass value="10108.464808585133" />
            <inertia ixx="3546.421372508591" iyy="3511.6717318932574" izz="6430.455520013371" ixy="-1.9671180192273086" iyz="-89.140091344758" ixz="-4.520646569848701" />
        </inertial>
        <visual name="base_link_visual">
            <origin xyz="0.0 0.0 0.0" rpy="0.0 0.0 0.0" />
            <geometry>
                <mesh filename="package://dku_robotarm/meshes/base_link.stl" scale="0.001 0.001 0.001" />
            </geometry>
            <material name="green"/>
        </visual>
        <collision name="base_link_collision">
            <origin xyz="0.0 0.0 0.0" rpy="0.0 0.0 0.0" />
            <geometry>
                <mesh filename="package://dku_robotarm/meshes/base_link.stl" scale="0.001 0.001 0.001" />
            </geometry>
        </collision>
    </link>
    <link name="link1">
        <inertial>
            <origin xyz="-0.0005191761096655689 0.13677259756813512 0.07844850630035381" rpy="0.0 -0.0 0.0" />
            <mass value="306.5786666425041" />
            <inertia ixx="17.93715320481499" iyy="14.598859090597351" izz="11.373863501818867" ixy="0.1696980225139425" iyz="3.272354529854188" ixz="-0.1769617229729228" />
        </inertial>
        <visual name="link1_visual">
            <origin xyz="-0.0005789437992247848 0.11001240803124696 0.24500000184248963" rpy="1.6512843464858685e-15 3.760936926924088e-15 1.5845124105542547" />
            <geometry>
                <mesh filename="package://dku_robotarm/meshes/link1.stl" scale="0.001 0.001 0.001" />
            </geometry>
            <material name="orange"/>
        </visual>
        <collision name="link1_collision">
            <origin xyz="-0.0005789437992247848 0.11001240803124696 0.24500000184248963" rpy="1.6512843464858685e-15 3.760936926924088e-15 1.5845124105542547" />
            <geometry>
                <mesh filename="package://dku_robotarm/meshes/link1.stl" scale="0.001 0.001 0.001" />
            </geometry>
        </collision>
    </link>
    <link name="link2">
        <inertial>
            <origin xyz="-0.2600222019323757 0.5047769414919006 0.004636792489645601" rpy="0.0 -2.519061796430787e-46 0.0" />
            <mass value="100.44717277373952" />
            <inertia ixx="9.114697552310073" iyy="6.379413374006056" izz="14.442416486127339" ixy="0.2501446719228537" iyz="-0.0205214969777296" ixz="0.07362224783218672" />
        </inertial>
        <visual name="link2_visual">
            <origin xyz="-0.43661628548635867 0.754190971358617 0.36333905883211776" rpy="-1.572915903078466 -0.013716083759361869 3.14159265358979" />
            <geometry>
                <mesh filename="package://dku_robotarm/meshes/link2.stl" scale="0.001 0.001 0.001" />
            </geometry>
            <material name="green"/>
        </visual>
        <collision name="link2_collision">
            <origin xyz="-0.43661628548635867 0.754190971358617 0.36333905883211776" rpy="-1.572915903078466 -0.013716083759361869 3.14159265358979" />
            <geometry>
                <mesh filename="package://dku_robotarm/meshes/link2.stl" scale="0.001 0.001 0.001" />
            </geometry>
        </collision>
    </link>
    <link name="link3">
        <inertial>
            <origin xyz="0.18996421933075738 -0.003886905448193332 -0.2679631167604811" rpy="-1.5777218093383881e-30 -0.0 0.0" />
            <mass value="326.31842277225974" />
            <inertia ixx="8.228786230621363" iyy="26.46373092097246" izz="21.187060492411078" ixy="-0.39807580342665644" iyz="0.03505895585752653" ixz="-0.6608875183880205" />
        </inertial>
        <visual name="link3_visual">
            <origin xyz="-0.8000047284187437 0.9945452368619254 -1.5578204277348136" rpy="-1.5708292695245774 -0.013716044201518205 1.5731981635635162" />
            <geometry>
                <mesh filename="package://dku_robotarm/meshes/link3.stl" scale="0.001 0.001 0.001" />
            </geometry>
            <material name="orange"/>
        </visual>
        <collision name="link3_collision">
            <origin xyz="-0.8000047284187437 0.9945452368619254 -1.5578204277348136" rpy="-1.5708292695245774 -0.013716044201518205 1.5731981635635162" />
            <geometry>
                <mesh filename="package://dku_robotarm/meshes/link3.stl" scale="0.001 0.001 0.001" />
            </geometry>
        </collision>
    </link>
    <link name="link4">
        <inertial>
            <origin xyz="-0.3959146800000012 3.396905979999999 -0.32274261000001153" rpy="0.0 -0.0 0.0" />
            <mass value="0.0" />
            <inertia ixx="0.0" iyy="0.0" izz="0.0" ixy="0.0" iyz="0.0" ixz="0.0" />
        </inertial>
        <visual name="link4_visual">
            <origin xyz="-8.468199390079821 -1.5571764986153063 0.5925673829405697" rpy="2.8274567775301698 1.556374444717997 -0.31416643989864734" />
            <geometry>
                <mesh filename="package://dku_robotarm/meshes/link4.stl" scale="0.001 0.001 0.001" />
            </geometry>
            <material name="green"/>
        </visual>
        <collision name="link4_collision">
            <origin xyz="-8.468199390079821 -1.5571764986153063 0.5925673829405697" rpy="2.8274567775301698 1.556374444717997 -0.31416643989864734" />
            <geometry>
                <mesh filename="package://dku_robotarm/meshes/link4.stl" scale="0.001 0.001 0.001" />
            </geometry>
        </collision>
    </link>
    <link name="link5">
        <inertial>
            <origin xyz="-0.22666962259582815 -0.28220578276067443 -0.18817046218692632" rpy="0.0 2.61056560398629e-35 0.0" />
            <mass value="262.6198877301529" />
            <inertia ixx="5.729736558600052" iyy="9.195138044485704" izz="6.486097380404312" ixy="-0.32375970186378783" iyz="-0.29393139772206545" ixz="-1.1696929316581306" />
        </inertial>
        <visual name="link5_visual">
            <origin xyz="-0.7009264406483555 -0.6525218975670868 2.730512689322356" rpy="-1.2566604507360546 -1.5563744447179888 2.8274262136906216" />
            <geometry>
                <mesh filename="package://dku_robotarm/meshes/link5.stl" scale="0.001 0.001 0.001" />
            </geometry>
            <material name="orange"/>
        </visual>
        <collision name="link5_collision">
            <origin xyz="-0.7009264406483555 -0.6525218975670868 2.730512689322356" rpy="-1.2566604507360546 -1.5563744447179888 2.8274262136906216" />
            <geometry>
                <mesh filename="package://dku_robotarm/meshes/link5.stl" scale="0.001 0.001 0.001" />
            </geometry>
        </collision>
    </link>
    <link name="main_gripper1">
        <inertial>
            <origin xyz="0.08652985520630295 -0.008625243214054326 0.0015421778757775506" rpy="-2.4872727037369403e-39 -0.0 0.0" />
            <mass value="11.975281293019925" />
            <inertia ixx="0.03777248574568687" iyy="0.25522336648143096" izz="0.22088163671287475" ixy="-0.003220071904213917" iyz="0.0004912406185813801" ixz="0.0023881937773753553" />
        </inertial>
        <visual name="main_gripper1_visual">
            <origin xyz="0.3647586941176263 -2.6858873633158895 -0.5433129351307635" rpy="-1.5708574570492382 0.013715947543604915 -1.575253311351206" />
            <geometry>
                <mesh filename="package://dku_robotarm/meshes/main_gripper1.stl" scale="0.001 0.001 0.001" />
            </geometry>
            <material name="green"/>
        </visual>
        <collision name="main_gripper1_collision">
            <origin xyz="0.3647586941176263 -2.6858873633158895 -0.5433129351307635" rpy="-1.5708574570492382 0.013715947543604915 -1.575253311351206" />
            <geometry>
                <mesh filename="package://dku_robotarm/meshes/main_gripper1.stl" scale="0.001 0.001 0.001" />
            </geometry>
        </collision>
    </link>
    <link name="main_gripper2">
        <inertial>
            <origin xyz="0.21418774992785586 0.04820608076139878 0.06156358409449574" rpy="-1.1652537746110059e-39 -0.0 0.0" />
            <mass value="14.367402646416181" />
            <inertia ixx="0.0291682947582029" iyy="0.4325225043076557" izz="0.40722982033253174" ixy="0.0028447843530079436" iyz="0.0006873088121905954" ixz="-0.07632608284802522" />
        </inertial>
        <visual name="main_gripper2_visual">
            <origin xyz="0.05725904411775048 -2.6585192833158935 -0.5429375251307398" rpy="-1.5708574570489884 0.013715947543604029 -1.5752533113511995" />
            <geometry>
                <mesh filename="package://dku_robotarm/meshes/main_gripper2.stl" scale="0.001 0.001 0.001" />
            </geometry>
            <material name="green"/>
        </visual>
        <collision name="main_gripper2_collision">
            <origin xyz="0.05725904411775048 -2.6585192833158935 -0.5429375251307398" rpy="-1.5708574570489884 0.013715947543604029 -1.5752533113511995" />
            <geometry>
                <mesh filename="package://dku_robotarm/meshes/main_gripper2.stl" scale="0.001 0.001 0.001" />
            </geometry>
        </collision>
    </link>
    <link name="sub_gripper1">
        <inertial>
            <origin xyz="0.07919190039094588 -0.04202901375102473 0.008572830681591839" rpy="-2.4872727037369403e-39 -0.0 0.0" />
            <mass value="12.566774937192251" />
            <inertia ixx="0.04238353040797782" iyy="0.2519919979597205" izz="0.21399497557260366" ixy="0.0003890952811973486" iyz="0.0004709308115309605" ixz="-0.0260459307912147" />
        </inertial>
        <visual name="sub_gripper1_visual">
            <origin xyz="0.362591633073269 -2.712540429257725 -0.8232914554731952" rpy="-1.5708574570485734 0.013715947543642222 -1.5752533113512082" />
            <geometry>
                <mesh filename="package://dku_robotarm/meshes/sub_gripper1.stl" scale="0.001 0.001 0.001" />
            </geometry>
            <material name="green"/>
        </visual>
        <collision name="sub_gripper1_collision">
            <origin xyz="0.362591633073269 -2.712540429257725 -0.8232914554731952" rpy="-1.5708574570485734 0.013715947543642222 -1.5752533113512082" />
            <geometry>
                <mesh filename="package://dku_robotarm/meshes/sub_gripper1.stl" scale="0.001 0.001 0.001" />
            </geometry>
        </collision>
    </link>
    <link name="sub_gripper2">
        <inertial>
            <origin xyz="0.21630154601689924 0.049757622738485545 -0.052231388210987294" rpy="-2.2871685465825514e-58 -2.61012178719941e-54 0.0" />
            <mass value="14.367402725616657" />
            <inertia ixx="0.024020890143751694" iyy="0.43254019180955083" izz="0.4123563529569766" ixy="0.0009685135409318603" iyz="2.3840390186806245e-07" ixz="0.06213718556551127" />
        </inertial>
        <visual name="sub_gripper2_visual">
            <origin xyz="0.05802396307325751 -2.6506222692577093 -0.8637126054731933" rpy="-1.5708574570485734 0.013715947543641359 -1.5752533113512064" />
            <geometry>
                <mesh filename="package://dku_robotarm/meshes/sub_gripper2.stl" scale="0.001 0.001 0.001" />
            </geometry>
            <material name="green"/>
        </visual>
        <collision name="sub_gripper2_collision">
            <origin xyz="0.05802396307325751 -2.6506222692577093 -0.8637126054731933" rpy="-1.5708574570485734 0.013715947543641359 -1.5752533113512064" />
            <geometry>
                <mesh filename="package://dku_robotarm/meshes/sub_gripper2.stl" scale="0.001 0.001 0.001" />
            </geometry>
        </collision>
    </link>
    <link name="end_effector">
        <visual>
        <origin xyz="0.0 0.0 0.0" rpy="0.0 0.0 0.0"/>
        <geometry>
            <box size="0.01 0.01 0.01"/>
        </geometry>
        </visual>
    </link>


    <joint name="base_joint" type="revolute">
        <origin xyz="0.10588036 0.32325529000000003 1.2519571" rpy="3.0656538569228853e-15 -0.0 0.0" />
        <parent link="base_link" />
        <child link="link1" />
        <axis xyz="0.0 3.0656538569228853e-15 1.0" />
        <limit lower="-1.584512" upper="1.55708" effort="1000000" velocity="1000000" />
    </joint>
    <joint name="link1_link2" type="revolute">
        <origin xyz="0.26726897000000016 0.01867753000000043 0.14999999999999972" rpy="1.570796326794891 -1.039256748674529e-31 -1.734723475977927e-18" />
        <parent link="link1" />
        <child link="link2" />
        <axis xyz="-0.9999059999999999 -3.5039334687439777e-17 0.013716000000006246" />
        <limit lower="-1.568677" upper="1.572916" effort="1000000" velocity="1000000" />
    </joint>
    <joint name="link2_link3" type="revolute">
        <origin xyz="2.993999999993946e-05 1.02999769 0.002182960000002652" rpy="1.5707963267949066 -2.5537647968680023e-15 1.5707963267948966" />
        <parent link="link2" />
        <child link="link3" />
        <axis xyz="-9.352162046422787e-21 0.013715999999990076 -0.999906" />
        <limit lower="-1.570514" upper="1.571078" effort="1000000" velocity="1000000" />
    </joint>
    <joint name="link3_link4" type="revolute">
        <origin xyz="0.9649511900000005 0.0170072500000002 0.022735409999999873" rpy="1.5707963267949 -1.5707963267948855 0" />
        <parent link="link3" />
        <child link="link4" />
        <axis xyz="-0.999906 -4.686685962499137e-17 -0.013715999999996302" />
        <limit lower="-1.577655" upper="1.563938" effort="1000000" velocity="1000000" />
    </joint>
    <joint name="link4_link5" type="revolute">
        <origin xyz="-0.343789430000001 -0.5786875400000008 -0.2721646099999981" rpy="-7.631778384881335e-15 1.8602830338647298e-19 4.2471464551046585e-19" />
        <parent link="link4" />
        <child link="link5" />
        <axis xyz="-6.100000000000043e-05 -0.9999900000000003 0.004455999999995753" />
        <limit lower="0.0" upper="3.141593" effort="1000000" velocity="1000000" />
    </joint>
    <joint name="end_effector" type="fixed">
        <origin xyz="0.01 -1.1 0.01" rpy="0.0 0.0 0.0"/>
        <parent link="link5"/>
        <child link="end_effector"/>
        <axis xyz="0 0 1.0"/>
    </joint>

    <joint name="main_gripper1" type="revolute">
        <origin xyz="-0.1575997900000001 -0.28776766000000065 0.04362542999999879" rpy="-1.5707963267948966 4.246440975279546e-15 -1.5707963267948966" />
        <parent link="link5" />
        <child link="main_gripper1" />
        <axis xyz="-0.004457 -0.999896 -0.013715999999999983" />
        <limit lower="-1.570796" upper="0.0" effort="1000000" velocity="1000000" />
    </joint>
    <joint name="main_gripper2" type="continuous">
        <origin xyz="0.30749964999999974 -0.02736808 -0.0003754099999999916" rpy="-9.330926015963404e-19 -0.0 1.8663967412030045e-21" />
        <parent link="main_gripper1" />
        <child link="main_gripper2" />
        <axis xyz="-0.004457 -0.999896 -0.013715999999999978" />
    </joint>
    <joint name="sub_gripper1" type="continuous">
        <origin xyz="0.12250216999999997 -0.2899748299999999 0.007973299999998771" rpy="-1.5707963267948966 4.246440975279546e-15 -1.5707963267948966" />
        <parent link="link5" />
        <child link="sub_gripper1" />
        <axis xyz="-0.004457 -0.999896 -0.013715999999999973" />
    </joint>
    <joint name="sub_gripper2" type="continuous">
        <origin xyz="0.30456767000000073 -0.06191816000000001 0.040421150000000024" rpy="-1.0251691368420165e-18 -8.673617379884035e-19 3.932017107160776e-21" />
        <parent link="sub_gripper1" />
        <child link="sub_gripper2" />
        <axis xyz="-0.004457 -0.999896 -0.013715999999999978" />
    </joint>
</robot>