<?xml version='1.0' encoding='utf-8'?>
<robot name="robotic_arm_6dof">
    <material name="green">
        <color rgba="0 0.6 0 1" />
    </material>
    <material name="orange">
        <color rgba="1.0 0.4 0.0 1.0"/>
    </material>

    <link name="base_link">
        <inertial>
            <origin xyz="0.0007383995830932366 0.016066406007732476 0.1863534219304777" rpy="0.0 0.0 0.0" />
            <mass value="10108.464808585133" />
            <inertia ixx="3546.421372508591" iyy="3511.6717318932574" izz="6430.455520013371" ixy="-1.9671180192273086" iyz="-89.140091344758" ixz="-4.520646569848701" />
        </inertial>
        <visual name="base_link_visual">
            <origin xyz="0.0 0.0 0.0" rpy="0.0 0.0 0.0" />
            <geometry>
                <mesh filename="package://dku_robotarm/meshes/base_link.stl" scale="0.001 0.001 0.001" />
            </geometry>
            <material name="green"/>
        </visual>
        <collision name="base_link_collision">
            <origin xyz="0.0 0.0 0.0" rpy="0.0 0.0 0.0" />
            <geometry>
                <mesh filename="package://dku_robotarm/meshes/base_link.stl" scale="0.001 0.001 0.001" />
            </geometry>
        </collision>
    </link>
    <link name="link1">
        <inertial>
            <origin xyz="-0.0005191761096655689 0.13677259756813512 0.07844850630035381" rpy="0.0 -0.0 0.0" />
            <mass value="306.5786666425041" />
            <inertia ixx="17.93715320481499" iyy="14.598859090597351" izz="11.373863501818867" ixy="0.1696980225139425" iyz="3.272354529854188" ixz="-0.1769617229729228" />
        </inertial>
        <visual name="link1_visual">
            <origin xyz="-0.0005789437992247848 0.11001240803124696 0.24500000184248963" rpy="1.6512843464858685e-15 3.760936926924088e-15 1.5845124105542547" />
            <geometry>
                <mesh filename="package://dku_robotarm/meshes/link1.stl" scale="0.001 0.001 0.001" />
            </geometry>
            <material name="orange"/>
        </visual>
        <collision name="link1_collision">
            <origin xyz="-0.0005789437992247848 0.11001240803124696 0.24500000184248963" rpy="1.6512843464858685e-15 3.760936926924088e-15 1.5845124105542547" />
            <geometry>
                <mesh filename="package://dku_robotarm/meshes/link1.stl" scale="0.001 0.001 0.001" />
            </geometry>
        </collision>
    </link>
    <link name="link2">
        <inertial>
            <origin xyz="-0.2600222019323757 0.5047769414919006 0.004636792489645601" rpy="0.0 -2.519061796430787e-46 0.0" />
            <mass value="100.44717277373952" />
            <inertia ixx="9.114697552310073" iyy="6.379413374006056" izz="14.442416486127339" ixy="0.2501446719228537" iyz="-0.0205214969777296" ixz="0.07362224783218672" />
        </inertial>
        <visual name="link2_visual">
            <origin xyz="-0.43661628548635867 0.754190971358617 0.36333905883211776" rpy="-1.572915903078466 -0.013716083759361869 3.14159265358979" />
            <geometry>
                <mesh filename="package://dku_robotarm/meshes/link2.stl" scale="0.001 0.001 0.001" />
            </geometry>
            <material name="green"/>
        </visual>
        <collision name="link2_collision">
            <origin xyz="-0.43661628548635867 0.754190971358617 0.36333905883211776" rpy="-1.572915903078466 -0.013716083759361869 3.14159265358979" />
            <geometry>
                <mesh filename="package://dku_robotarm/meshes/link2.stl" scale="0.001 0.001 0.001" />
            </geometry>
        </collision>
    </link>
    <link name="link3">
        <inertial>
            <origin xyz="0.18996421933075738 -0.003886905448193332 -0.2679631167604811" rpy="-1.5777218093383881e-30 -0.0 0.0" />
            <mass value="326.31842277225974" />
            <inertia ixx="8.228786230621363" iyy="26.46373092097246" izz="21.187060492411078" ixy="-0.39807580342665644" iyz="0.03505895585752653" ixz="-0.6608875183880205" />
        </inertial>
        <visual name="link3_visual">
            <origin xyz="-0.8000047284187437 0.9945452368619254 -1.5578204277348136" rpy="-1.5708292695245774 -0.013716044201518205 1.5731981635635162" />
            <geometry>
                <mesh filename="package://dku_robotarm/meshes/link3.stl" scale="0.001 0.001 0.001" />
            </geometry>
            <material name="orange"/>
        </visual>
        <collision name="link3_collision">
            <origin xyz="-0.8000047284187437 0.9945452368619254 -1.5578204277348136" rpy="-1.5708292695245774 -0.013716044201518205 1.5731981635635162" />
            <geometry>
                <mesh filename="package://dku_robotarm/meshes/link3.stl" scale="0.001 0.001 0.001" />
            </geometry>
        </collision>
    </link>
    <link name="link4">
        <inertial>
            <origin xyz="-0.3959146800000012 3.396905979999999 -0.32274261000001153" rpy="0.0 -0.0 0.0" />
            <mass value="0.0" />
            <inertia ixx="0.0" iyy="0.0" izz="0.0" ixy="0.0" iyz="0.0" ixz="0.0" />
        </inertial>
        <visual name="link4_visual">
            <origin xyz="-8.468199390079821 -1.5571764986153063 0.5925673829405697" rpy="2.8274567775301698 1.556374444717997 -0.31416643989864734" />
            <geometry>
                <mesh filename="package://dku_robotarm/meshes/link4.stl" scale="0.001 0.001 0.001" />
            </geometry>
            <material name="green"/>
        </visual>
        <collision name="link4_collision">
            <origin xyz="-8.468199390079821 -1.5571764986153063 0.5925673829405697" rpy="2.8274567775301698 1.556374444717997 -0.31416643989864734" />
            <geometry>
                <mesh filename="package://dku_robotarm/meshes/link4.stl" scale="0.001 0.001 0.001" />
            </geometry>
        </collision>
    </link>
    <link name="link5">
        <inertial>
            <origin xyz="0.18940864102503166 -0.2873970506681644 -0.22537398346944218" rpy="0.0 2.61056560398629e-35 0.0" />
            <mass value="262.6198877301529" />
            <inertia ixx="6.483566080809396" iyy="9.194720079461973" izz="5.732685823195425" ixy="0.2873012032335347" iyz="-0.3342681416309991" ixz="1.1698186807578765" />
        </inertial>
        <visual name="link5_visual">
            <origin xyz="-2.7276187812550865 -0.6726756531178216 -0.6978952098911387" rpy="-1.5663397614748251 0.013716083759338395 -3.1415926535897776" />
            <geometry>
                <mesh filename="package://dku_robotarm/meshes/link5.stl" scale="0.001 0.001 0.001" />
            </geometry>
            <material name="orange"/>
        </visual>
        <collision name="link5_collision">
            <origin xyz="-2.7276187812550865 -0.6726756531178216 -0.6978952098911387" rpy="-1.5663397614748251 0.013716083759338395 -3.1415926535897776" />
            <geometry>
                <mesh filename="package://dku_robotarm/meshes/link5.stl" scale="0.001 0.001 0.001" />
            </geometry>
        </collision>
    </link>
    <link name="main_gripper1">
        <inertial>
            <origin xyz="0.0865590835194024 -0.001933208470501242 -0.00824485825067416" rpy="-3.0814969681669147e-33 1.504632769052528e-36 4.176194859519056e-53" />
            <mass value="11.975281293019925" />
            <inertia ixx="0.03778716981280465" iyy="0.22089945714841974" izz="0.2551908619775247" ixy="-0.0015589188381204264" iyz="-0.0004828643403727328" ixz="-0.0041778603590669474" />
        </inertial>
        <visual name="main_gripper1_visual">
            <origin xyz="0.3790101131178119 0.5416063642373468 -2.684258305319082" rpy="1.5752528921149982 1.5570802430355946 1.5707963267935876" />
            <geometry>
                <mesh filename="package://dku_robotarm/meshes/main_gripper1.stl" scale="0.001 0.001 0.001" />
            </geometry>
            <material name="green"/>
        </visual>
        <collision name="main_gripper1_collision">
            <origin xyz="0.3790101131178119 0.5416063642373468 -2.684258305319082" rpy="1.5752528921149982 1.5570802430355946 1.5707963267935876" />
            <geometry>
                <mesh filename="package://dku_robotarm/meshes/main_gripper1.stl" scale="0.001 0.001 0.001" />
            </geometry>
        </collision>
    </link>
    <link name="main_gripper2">
        <inertial>
            <origin xyz="0.21369352959919183 -0.06252952979282421 0.04914697204853748" rpy="-5.66003746983411e-57 -0.0 0.0" />
            <mass value="14.367402646416181" />
            <inertia ixx="0.02984837784477204" iyy="0.40653252301268594" izz="0.4325397185392603" ixy="0.07803311211620789" iyz="-0.00035668704149891174" ixz="0.0010703461995382694" />
        </inertial>
        <visual name="main_gripper2_visual">
            <origin xyz="0.07139458311793419 0.542620544237323 -2.6582419553190877" rpy="1.575252892114777 1.5570802430355957 1.5707963267932044" />
            <geometry>
                <mesh filename="package://dku_robotarm/meshes/main_gripper2.stl" scale="0.001 0.001 0.001" />
            </geometry>
            <material name="green"/>
        </visual>
        <collision name="main_gripper2_collision">
            <origin xyz="0.07139458311793419 0.542620544237323 -2.6582419553190877" rpy="1.575252892114777 1.5570802430355957 1.5707963267932044" />
            <geometry>
                <mesh filename="package://dku_robotarm/meshes/main_gripper2.stl" scale="0.001 0.001 0.001" />
            </geometry>
        </collision>
    </link>
    <link name="sub_gripper1">
        <inertial>
            <origin xyz="0.07933631784319403 -0.00893131021874968 -0.04168055926730681" rpy="-3.0814969681669147e-33 1.504632769052528e-36 4.176194859519056e-53" />
            <mass value="12.566774937192251" />
            <inertia ixx="0.0426229871859181" iyy="0.213756147487004" izz="0.2519913692667046" ixy="0.02682188789489714" iyz="-0.0003540466040550929" ixz="-0.0005337464952771285" />
        </inertial>
        <visual name="sub_gripper1_visual">
            <origin xyz="0.37822496311833503 0.8215912833539488 -2.7109206418950844" rpy="1.5752528921156685 1.557080243035557 1.5707963267939096" />
            <geometry>
                <mesh filename="package://dku_robotarm/meshes/sub_gripper1.stl" scale="0.001 0.001 0.001" />
            </geometry>
            <material name="green"/>
        </visual>
        <collision name="sub_gripper1_collision">
            <origin xyz="0.37822496311833503 0.8215912833539488 -2.7109206418950844" rpy="1.5752528921156685 1.557080243035557 1.5707963267939096" />
            <geometry>
                <mesh filename="package://dku_robotarm/meshes/sub_gripper1.stl" scale="0.001 0.001 0.001" />
            </geometry>
        </collision>
    </link>
    <link name="sub_gripper2">
        <inertial>
            <origin xyz="0.21631451607317218 0.05125476390756667 0.05070778377501411" rpy="-5.478173897492628e-58 -7.523163845262642e-37 0.0" />
            <mass value="14.367402725616657" />
            <inertia ixx="0.023466824303598637" iyy="0.4129097966231824" izz="0.4325408139821434" ixy="-0.06037985319979809" iyz="-0.00026959338026765053" ixz="-0.0008281779560013491" />
        </inertial>
        <visual name="sub_gripper2_visual">
            <origin xyz="0.07357381311832568 0.8633890533539474 -2.650341661895067" rpy="1.5752528921155384 1.5570802430355586 1.5707963267937881" />
            <geometry>
                <mesh filename="package://dku_robotarm/meshes/sub_gripper2.stl" scale="0.001 0.001 0.001" />
            </geometry>
            <material name="green"/>
        </visual>
        <collision name="sub_gripper2_collision">
            <origin xyz="0.07357381311832568 0.8633890533539474 -2.650341661895067" rpy="1.5752528921155384 1.5570802430355586 1.5707963267937881" />
            <geometry>
                <mesh filename="package://dku_robotarm/meshes/sub_gripper2.stl" scale="0.001 0.001 0.001" />
            </geometry>
        </collision>
    </link>
    <link name="end_effector">
        <visual>
        <origin xyz="0.0 0.0 0.0" rpy="0.0 0.0 0.0"/>
        <geometry>
            <box size="0.01 0.01 0.01"/>
        </geometry>
        </visual>
    </link>


    <joint name="base_joint" type="revolute">
        <origin xyz="0.10588036 0.32325529000000003 1.2519571" rpy="3.0656538569228853e-15 -0.0 0.0" />
        <parent link="base_link" />
        <child link="link1" />
        <axis xyz="0.0 3.0656538569228853e-15 1.0" />
        <limit lower="-1.584512" upper="1.55708" effort="1000000" velocity="1000000" />
    </joint>
    <joint name="link1_link2" type="revolute">
        <origin xyz="0.26726897000000016 0.01867753000000043 0.14999999999999972" rpy="1.570796326794891 -1.039256748674529e-31 -1.734723475977927e-18" />
        <parent link="link1" />
        <child link="link2" />
        <axis xyz="-0.9999059999999999 -3.5039334687439777e-17 0.013716000000006246" />
        <limit lower="-1.568677" upper="1.572916" effort="1000000" velocity="1000000" />
    </joint>
    <joint name="link2_link3" type="revolute">
        <origin xyz="2.993999999993946e-05 1.02999769 0.002182960000002652" rpy="1.5707963267949066 -2.5537647968680023e-15 1.5707963267948966" />
        <parent link="link2" />
        <child link="link3" />
        <axis xyz="-9.352162046422787e-21 0.013715999999990076 -0.999906" />
        <limit lower="-1.570514" upper="1.571078" effort="1000000" velocity="1000000" />
    </joint>
    <joint name="link3_link4" type="revolute">
        <origin xyz="0.9649511900000005 0.0170072500000002 0.022735409999999873" rpy="1.5707963267949 -1.5707963267948855 0" />
        <parent link="link3" />
        <child link="link4" />
        <axis xyz="-0.999906 -4.686685962499137e-17 -0.013715999999996302" />
        <limit lower="-1.577655" upper="1.563938" effort="1000000" velocity="1000000" />
    </joint>
    <joint name="link4_link5" type="revolute">
        <origin xyz="-0.343789430000001 -0.5786875400000008 -0.2721646099999981" rpy="-7.631778384881335e-15 1.8602830338647298e-19 4.2471464551046585e-19" />
        <parent link="link4" />
        <child link="link5" />
        <axis xyz="-6.100000000000043e-05 -0.9999900000000003 0.004455999999995753" />
        <limit lower="-1.570796" upper="1.570796" effort="1000000" velocity="1000000" />
    </joint>
    <joint name="end_effector" type="fixed">
        <origin xyz="0.01 -1.1 0.01" rpy="0.0 0.0 0.0"/>
        <parent link="link5"/>
        <child link="end_effector"/>
        <axis xyz="0 0 1.0"/>
    </joint>

    <joint name="main_gripper1" type="revolute">
        <origin xyz="-0.04236056999999972 -0.2936655399999995 -0.15627513000000126" rpy="-1.5707963267948966 4.2464459612885334e-15 -1.5707963267948966" />
        <parent link="link5" />
        <child link="main_gripper1" />
        <axis xyz="-1.0441198370741651e-20 0.013715999999999978 -0.999906" />
        <limit lower="-1.570796" upper="0.0" effort="1000000" velocity="1000000" />
    </joint>
    <joint name="main_gripper2" type="continuous">
        <origin xyz="0.3076155299999999 -0.0010141800000000067 -0.02601635" rpy="-5.157061093467415e-19 -6.581780574186106e-21 -8.673617379884034e-19" />
        <parent link="main_gripper1" />
        <child link="main_gripper2" />
        <axis xyz="-2.8919093855802717e-20 0.013715999999999978 -0.999906" />
    </joint>
    <joint name="sub_gripper1" type="continuous">
        <origin xyz="-0.006699080000000226 -0.29445069000000046 0.12383322999999877" rpy="-1.5707963267948966 4.2464459612885334e-15 -1.5707963267948966" />
        <parent link="link5" />
        <child link="sub_gripper1" />
        <axis xyz="-1.0441198370741651e-20 0.013715999999999978 -0.999906" />
    </joint>
    <joint name="sub_gripper2" type="continuous">
        <origin xyz="0.30465115000000026 -0.04179776999999998 -0.06057898" rpy="1.5641892085563873e-18 6.201604855142745e-21 -1.3835674616372782e-37" />
        <parent link="sub_gripper1" />
        <child link="sub_gripper2" />
        <axis xyz="-4.2401764664552925e-21 0.013715999999999975 -0.999906" />
    </joint>
</robot>