<?xml version='1.0' encoding='utf-8'?>
<robot name="robotic_arm_6dof">
    <material name="green">
        <color rgba="0 0.6 0 1" />
    </material>
    <material name="orange">
        <color rgba="1.0 0.4 0.0 1.0"/>
    </material>
    <link name="base_link">
        <inertial>
            <origin xyz="0.01606640600773284 -0.0007383995830934898 0.18635342193047766" rpy="0.0 0.0 0.0" />
            <mass value="10108.464808585133" />
            <inertia ixx="3511.671731893263" iyy="3546.4213725085874" izz="6430.455520013375" ixy="1.9671180192257547" iyz="4.520646569847874" ixz="-89.14009134475768" />
        </inertial>
        <visual name="base_link_visual">
            <origin xyz="0.0 0.0 0.0" rpy="0.0 0.0 0.0" />
            <geometry>
                <mesh filename="package://dku_robotarm/meshes/base_link.stl" scale="0.001 0.001 0.001" />
            </geometry>
            <material name="green"/>
        </visual>
        <collision name="base_link_collision">
            <origin xyz="0.0 0.0 0.0" rpy="0.0 0.0 0.0" />
            <geometry>
                <mesh filename="package://dku_robotarm/meshes/base_link.stl" scale="0.001 0.001 0.001" />
            </geometry>
        </collision>
    </link>
    <link name="link1">
        <inertial>
            <origin xyz="0.13673918076102454 -0.003067482882737824 0.07844850848209646" rpy="0.0 -0.0 0.0" />
            <mass value="306.57866664253083" />
            <inertia ixx="14.592262584738023" iyy="17.94375914298996" izz="11.373863517076138" ixy="-0.0819572817932435" iyz="0.09109221815427962" ixz="3.2758696517762593" />
        </inertial>
        <visual name="link1_visual">
            <origin xyz="0.09242569192283874 0.3864322595244824 6.951399081197209" rpy="3.2738006412295722e-15 1.431716633805285e-14 -0.012509138322026858" />
            <geometry>
                <mesh filename="package://dku_robotarm/meshes/link1.stl" scale="0.001 0.001 0.001" />
            </geometry>
            <material name="orange"/>
        </visual>
        <collision name="link1_collision">
            <origin xyz="0.09242569192283874 0.3864322595244824 6.951399081197209" rpy="3.2738006412295722e-15 1.431716633805285e-14 -0.012509138322026858" />
            <geometry>
                <mesh filename="package://dku_robotarm/meshes/link1.stl" scale="0.001 0.001 0.001" />
            </geometry>
        </collision>
    </link>
    <link name="link2">
        <inertial>
            <origin xyz="0.0032529940409223457 0.5047780757410013 -0.2600409911628012" rpy="0.0 6.935860747407658e-46 0.0" />
            <mass value="100.44717038799456" />
            <inertia ixx="14.442635789428664" iyy="6.379377146138694" izz="9.114514446368787" ixy="-0.00313598555666789" iyz="0.25038352746226894" ixz="0.06666659111011956" />
        </inertial>
        <visual name="link2_visual">
            <origin xyz="-0.06318113789706722 -0.04999999815745127 -0.14580172699212302" rpy="-1.5707963267949014 0.012509138321974865 3.141592653589779" />
            <geometry>
                <mesh filename="package://dku_robotarm/meshes/link2.stl" scale="0.001 0.001 0.001" />
            </geometry>
            <material name="green"/>
        </visual>
        <collision name="link2_collision">
            <origin xyz="-0.06318113789706722 -0.04999999815745127 -0.14580172699212302" rpy="-1.5707963267949014 0.012509138321974865 3.141592653589779" />
            <geometry>
                <mesh filename="package://dku_robotarm/meshes/link2.stl" scale="0.001 0.001 0.001" />
            </geometry>
        </collision>
    </link>
    <link name="link3">
        <inertial>
            <origin xyz="0.011368350293437501 -0.189945550890439 0.2677633379109025" rpy="0.0 -0.0 0.0" />
            <mass value="326.3184161312811" />
            <inertia ixx="26.463821633077714" iyy="8.22693165448494" izz="21.18880091709798" ixy="-0.37148137106885337" iyz="-0.6508449884904267" ixz="-0.10177317792577649" />
        </inertial>
        <visual name="link3_visual">
            <origin xyz="0.7146045554135309 -0.40764545168228095 1.5624981248299645" rpy="1.5707963267948974 0.012509138321568638 1.4276283841584992e-14" />
            <geometry>
                <mesh filename="package://dku_robotarm/meshes/link3.stl" scale="0.001 0.001 0.001" />
            </geometry>
            <material name="orange"/>
        </visual>
        <collision name="link3_collision">
            <origin xyz="0.7146045554135309 -0.40764545168228095 1.5624981248299645" rpy="1.5707963267948974 0.012509138321568638 1.4276283841584992e-14" />
            <geometry>
                <mesh filename="package://dku_robotarm/meshes/link3.stl" scale="0.001 0.001 0.001" />
            </geometry>
        </collision>
    </link>
    <link name="link4">
        <inertial>
            <origin xyz="-0.31963773000000145 3.394947099999999 0.39585780000001153" rpy="0.0 -0.0 0.0" />
            <mass value="0.0" />
            <inertia ixx="0.0" iyy="0.0" izz="0.0" ixy="0.0" iyz="0.0" ixz="0.0" />
        </inertial>
        <visual name="link4_visual">
            <origin xyz="0.6104392661876841 0.3653392047661822 -7.3004824302851095" rpy="-3.1415926535897922 -0.012509138321956204 -3.141592653589779" />
            <geometry>
                <mesh filename="package://dku_robotarm/meshes/link4.stl" scale="0.001 0.001 0.001" />
            </geometry>
            <material name="green"/>
        </visual>
        <collision name="link4_collision">
            <origin xyz="0.6104392661876841 0.3653392047661822 -7.3004824302851095" rpy="-3.1415926535897922 -0.012509138321956204 -3.141592653589779" />
            <geometry>
                <mesh filename="package://dku_robotarm/meshes/link4.stl" scale="0.001 0.001 0.001" />
            </geometry>
        </collision>
    </link>
    <link name="link5">
        <inertial>
            <origin xyz="0.183417704443965 0.281378329896296 0.23154163513079964" rpy="0.0 9.031806508343548e-47 0.0" />
            <mass value="262.6198877301529" />
            <inertia ixx="6.544409918945348" iyy="9.197664863785779" izz="5.6688972008514575" ixy="-0.27346419732867333" iyz="-0.3260390685368136" ixz="-1.149738047728069" />
        </inertial>
        <visual name="link5_visual">
            <origin xyz="-2.745018642394927 0.6647257915439394 0.6291220413596154" rpy="1.570796326794893 0.012509138321956203 -3.141592653589663" />
            <geometry>
                <mesh filename="package://dku_robotarm/meshes/link5.stl" scale="0.001 0.001 0.001" />
            </geometry>
            <material name="orange"/>
        </visual>
        <collision name="link5_collision">
            <origin xyz="-2.745018642394927 0.6647257915439394 0.6291220413596154" rpy="1.570796326794893 0.012509138321956203 -3.141592653589663" />
            <geometry>
                <mesh filename="package://dku_robotarm/meshes/link5.stl" scale="0.001 0.001 0.001" />
            </geometry>
        </collision>
    </link>

    <link name="main_gripper1">
        <inertial>
            <origin xyz="0.08656733986628411 -0.0017629960516340403 -0.008196159187131256" rpy="-3.0814879110195774e-33 -0.0 0.0" />
            <mass value="11.975281293019925" />
            <inertia ixx="0.037805210527008304" iyy="0.2208792200192421" izz="0.255193058396742" ixy="-0.0024838170934167185" iyz="0.00039839688853803777" ixz="-0.00412524240710115" />
        </inertial>
        <visual name="main_gripper1_visual">
            <origin xyz="0.37675695154394534 0.4727168601717002 -2.6975584806331803" rpy="-1.570796326805324 1.5582871884729403 -1.5707963268052356" />
            <geometry>
                <mesh filename="package://dku_robotarm/meshes/main_gripper1.stl" scale="0.001 0.001 0.001" />
            </geometry>'
            <material name="green"/>
        </visual>
        <collision name="main_gripper1_collision">
            <origin xyz="0.37675695154394534 0.4727168601717002 -2.6975584806331803" rpy="-1.570796326805324 1.5582871884729403 -1.5707963268052356" />
            <geometry>
                <mesh filename="package://dku_robotarm/meshes/main_gripper1.stl" scale="0.001 0.001 0.001" />
            </geometry>
        </collision>
    </link>

    <link name="main_gripper2">
        <inertial>
            <origin xyz="0.21396704535089725 -0.06026640616517037 0.05075781293416712" rpy="-3.0814879110195774e-33 -0.0 0.0" />
            <mass value="14.367402646416181" />
            <inertia ixx="0.029160283465793635" iyy="0.40721969257623436" izz="0.4325406433569585" ixy="0.07635270458822598" iyz="0.0003169285715139886" ixz="-0.0009551865195889296" />
        </inertial>
        <visual name="main_gripper2_visual">
            <origin xyz="0.06913837154394287 0.4730420901717 -2.6715605206331805" rpy="-1.570796326805324 1.5582871884729403 -1.5707963268053333" />
            <geometry>
                <mesh filename="package://dku_robotarm/meshes/main_gripper2.stl" scale="0.001 0.001 0.001" />
            </geometry>
            <material name="green"/>
        </visual>
        <collision name="main_gripper2_collision">
            <origin xyz="0.06913837154394287 0.4730420901717 -2.6715605206331805" rpy="-1.570796326805324 1.5582871884729403 -1.5707963268053333" />
            <geometry>
                <mesh filename="package://dku_robotarm/meshes/main_gripper2.stl" scale="0.001 0.001 0.001" />
            </geometry>
        </collision>
    </link>
    <link name="sub_gripper1">
        <inertial>
            <origin xyz="0.07937787617828918 -0.009667554849431825 -0.041436454677579664" rpy="-3.0814879110195774e-33 -0.0 0.0" />
            <mass value="12.566774937192251" />
            <inertia ixx="0.04238740988759483" iyy="0.21399931669904515" izz="0.2519837773529049" ixy="0.026035009420949613" iyz="0.0006417428542966907" ixz="-0.0012280898404568052" />
        </inertial>
        <visual name="sub_gripper1_visual">
            <origin xyz="0.37472579154394 0.7519000894805044 -2.731553394777437" rpy="-1.570796326805324 1.5582871884729403 -1.5707963268054308" />
            <geometry>
                <mesh filename="package://dku_robotarm/meshes/sub_gripper1.stl" scale="0.001 0.001 0.001" />
            </geometry>
            <material name="green"/>
        </visual>
        <collision name="sub_gripper1_collision">
            <origin xyz="0.37472579154394 0.7519000894805044 -2.731553394777437" rpy="-1.570796326805324 1.5582871884729403 -1.5707963268054308" />
            <geometry>
                <mesh filename="package://dku_robotarm/meshes/sub_gripper1.stl" scale="0.001 0.001 0.001" />
            </geometry>
        </collision>
    </link>
    <link name="sub_gripper2">
        <inertial>
            <origin xyz="0.21608087379048413 0.0535302308726496 0.049334281468440544" rpy="-3.0814879110195774e-33 -0.0 0.0" />
            <mass value="14.367402725616657" />
            <inertia ixx="0.02401277590084991" iyy="0.41236329502584135" izz="0.43254136398104515" ixy="-0.06211381189915867" iyz="0.00025219802789557726" ixz="0.0007770810834215298" />
        </inertial>
        <visual name="sub_gripper2_visual">
            <origin xyz="0.0698877115439393 0.7939139794805035 -2.672074284777439" rpy="-1.570796326805324 1.5582871884729401 -1.5707963268054308" />
            <geometry>
                <mesh filename="package://dku_robotarm/meshes/sub_gripper2.stl" scale="0.001 0.001 0.001" />
            </geometry>
            <material name="green"/>
        </visual>
        <collision name="sub_gripper2_collision">
            <origin xyz="0.0698877115439393 0.7939139794805035 -2.672074284777439" rpy="-1.570796326805324 1.5582871884729401 -1.5707963268054308" />
            <geometry>
                <mesh filename="package://dku_robotarm/meshes/sub_gripper2.stl" scale="0.001 0.001 0.001" />
            </geometry>
        </collision>
    </link>

    <link name="end_effector">
        <visual>
        <origin xyz="0.0 0.0 0.0" rpy="0.0 0.0 0.0"/>
        <geometry>
            <box size="0.01 0.01 0.01"/>
        </geometry>
        </visual>
    </link>

    <joint name="base_joint" type="revolute">
        <origin xyz="0.32325529000000003 -0.10588036 1.2499571" rpy="-9.62963850713621e-16 -0.0 0.0" />
        <parent link="base_link" />
        <child link="link1" />
        <axis xyz="0.0 -9.62963850713621e-16 1.0" />
        <limit lower="-1.570796" upper="1.570796" effort="1000000" velocity="1000000" />
    </joint>
    <joint name="link1_link2" type="revolute">
        <origin xyz="0.01166272000000042 -0.26766683000000013 0.14999999999999986" rpy="1.570796326794895 -6.3108872417680615e-30 -3.398971393601724e-29" />
        <parent link="link1" />
        <child link="link2" />
        <axis xyz="0.012509 2.5544328972976203e-15 -0.9999220000000001" />
        <limit lower="-1.570796" upper="1.570796" effort="1000000" velocity="1000000" />
    </joint>
    <joint name="link2_link3" type="revolute">
        <origin xyz="0.0 1.03 2.6290081223123707e-15" rpy="-3.1415926535897882 6.322045984118727e-29 -6.3108872417679326e-30" />
        <parent link="link2" />
        <child link="link3" />
        <axis xyz="0.012509 2.3944382140311698e-15 0.9999219999999999" />
        <limit lower="-1.570796" upper="1.570796" effort="1000000" velocity="1000000" />
    </joint>
    <joint name="link3_link4" type="revolute">
        <origin xyz="-0.01528028000000031 -0.9649900000000002 -0.022310609999997694" rpy="-5.779955626391973e-15 7.177747304298343e-29 -1.7188013101093054e-43" />
        <parent link="link3" />
        <child link="link4" />
        <axis xyz="0.012509 -3.385066575821944e-15 0.999922" />
        <limit lower="-1.570796" upper="1.570796" effort="1000000" velocity="1000000" />
    </joint>
    <joint name="link4_link5" type="revolute">
        <origin xyz="-0.2656321800000013 -0.5774900000000014 0.35084018999999805" rpy="3.1415926535897922 -4.096313271485057e-29 -1.7347234760422044e-18" />
        <parent link="link4" />
        <child link="link5" />
        <axis xyz="1.7347234760422044e-18 1.0 4.462142461080891e-15" />
        <limit lower="0.0" upper="3.141593" effort="1000000" velocity="1000000" />
    </joint>
    <joint name="end_effector" type="revolute">
        <origin xyz="0 1.1 -0.01" rpy="0.0 0.0 0.0"/>
        <parent link="link5"/>
        <child link="end_effector"/>
        <axis xyz="0 0 1.0"/>
        <limit lower="-1.57" upper="1.57" effort="0.92" velocity="5.24"/>
    </joint>

    <joint name="main_gripper1" type="revolute">
        <origin xyz="-0.04646024 0.2879688399999986 0.15641769000000127" rpy="1.5707963267948966 -4.462142461080891e-15 1.5707963267948966" />
        <parent link="link5" />
        <child link="main_gripper1" />
        <axis xyz="0.0 -0.012509000000000027 -0.9999220000000002" />
        <limit lower="-1.570796" upper="1.570796" effort="1000000" velocity="1000000" />
    </joint>
    <joint name="main_gripper2" type="revolute">
        <origin xyz="0.3076185800000002 -0.00032522999999994083 -0.025997959999999997" rpy="-1.734723475976844e-18 -2.5243548967072372e-29 6.037595893715346e-46" />
        <parent link="main_gripper1" />
        <child link="main_gripper2" />
        <axis xyz="-2.5241579970252946e-29 -0.012509000000000025 -0.9999220000000002" />
        <limit lower="-1.570796" upper="1.570796" effort="1000000" velocity="1000000" />
    </joint>
    <joint name="sub_gripper1" type="revolute">
        <origin xyz="-0.00346603 0.2900000000000006 -0.12265295999999871" rpy="1.5707963267948966 -4.462142461080891e-15 1.5707963267948966" />
        <parent link="link5" />
        <child link="sub_gripper1" />
        <axis xyz="0.0 -0.012509000000000027 -0.9999220000000002" />
        <limit lower="-1.570796" upper="1.570796" effort="1000000" velocity="1000000" />
    </joint>
    <joint name="sub_gripper2" type="revolute">
        <origin xyz="0.30483807999999957 -0.04201389 -0.05947910999999998" rpy="-1.7347234759768194e-18 -2.5243548967072372e-29 6.0375958937149105e-46" />
        <parent link="sub_gripper1" />
        <child link="sub_gripper2" />
        <axis xyz="-2.5241579970252946e-29 -0.012509000000000025 -0.9999220000000002" />
        <limit lower="-1.570796" upper="1.570796" effort="1000000" velocity="1000000" />
    </joint>
</robot>